Workbook

Sheet Overview
H1: Focus Area | J1: =#REF! -> #REF! | M1: ='M274'!J1 -> Slow down hackers | P1: =#REF! -> #REF! | S1: =#REF! -> #REF! | V1: Increase Detection | Y1: Increase Detection | AB1: Increase Detection | AE1: Increase Detection | AH1: Reduce Damage | AK1: Reduce Damage | AN1: Reduce Damage | AQ1: Reduce Damage | AT1: Reduce Damage | AW1: Streamline Compliance | AZ1: Streamline Compliance | BC1: Streamline Compliance | BF1: Build Security Organization / Skills | BI1: Build Security Organization / Skills | BL1: Build Security Organization / Skills
A2: IT Security Initiative | J2: =#REF! -> #REF! | M2: ='M274'!J2 -> M274 | N2: #REF! | P2: =#REF! -> #REF! | S2: =#REF! -> #REF! | V2: =#REF! -> #REF! | Y2: =#REF! -> #REF! | AB2: =#REF! -> #REF! | AE2: =#REF! -> #REF! | AH2: =#REF! -> #REF! | AK2: =#REF! -> #REF! | AN2: =#REF! -> #REF! | AQ2: =#REF! -> #REF! | AT2: =#REF! -> #REF! | AW2: =#REF! -> #REF! | AZ2: =#REF! -> #REF! | BC2: =#REF! -> #REF! | BF2: =#REF! -> #REF! | BI2: =#REF! -> #REF! | BJ2: 0 | BL2: =#REF! -> #REF! | BM2: 0
A3: Progress KPI Reporting 2021 | J3: =#REF! -> #REF! | M3: ='M274'!J3 -> # of scenarios tested | N3: #REF! | P3: =#REF! -> #REF! | S3: =#REF! -> #REF! | V3: =#REF! -> #REF! | Y3: =#REF! -> #REF! | AB3: =#REF! -> #REF! | AE3: =#REF! -> #REF! | AH3: =#REF! -> #REF! | AK3: =#REF! -> #REF! | AN3: =#REF! -> #REF! | AQ3: =#REF! -> #REF! | AT3: =#REF! -> #REF! | AW3: =#REF! -> #REF! | AZ3: =#REF! -> #REF! | BC3: =#REF! -> #REF! | BF3: =#REF! -> #REF! | BI3: =#REF! -> #REF! | BJ3: 1 | BL3: =#REF! -> #REF! | BM3: 1
A4: as of 04.09.2020 | J4: =#REF! -> #REF! | K4: =#REF! -> #REF! | M4: ='M274'!J4 -> 4 | N4: ='M274'!K4 -> 0 | P4: =#REF! -> #REF! | Q4: =#REF! -> #REF! | S4: =#REF! -> #REF! | T4: =#REF! -> #REF! | V4: =#REF! -> #REF! | W4: =#REF! -> #REF! | Y4: =#REF! -> #REF! | Z4: =#REF! -> #REF! | AB4: =#REF! -> #REF! | AC4: =#REF! -> #REF! | AE4: =#REF! -> #REF! | AF4: =#REF! -> #REF! | AH4: =#REF! -> #REF! | AI4: =#REF! -> #REF! | AK4: =#REF! -> #REF! | AL4: =#REF! -> #REF! | AN4: =#REF! -> #REF! | AO4: =#REF! -> #REF! | AQ4: =#REF! -> #REF! | AR4: =#REF! -> #REF! | AT4: =#REF! -> #REF! | AU4: =#REF! -> #REF! | AW4: =#REF! -> #REF! | AX4: =#REF! -> #REF! | AZ4: =#REF! -> #REF! | BA4: =#REF! -> #REF! | BC4: =#REF! -> #REF! | BD4: =#REF! -> #REF! | BF4: =#REF! -> #REF! | BG4: =#REF! -> #REF! | BI4: =#REF! -> #REF! | BJ4: =#REF! -> #REF! | BL4: =#REF! -> #REF! | BM4: =#REF! -> #REF!
A5: Board Members | B5: H Ressort | C5: ITC Mapping | E5: Group Iso Function | F5: OEs ID | G5: CIM ID | H5: OE | J5: =#REF! -> #REF! | K5: =#REF! -> #REF! | M5: ='M274'!J5 -> Target 31.12.21 | N5: ='M274'!K5 -> Actuals 24.09.21 | P5: =#REF! -> #REF! | Q5: =#REF! -> #REF! | S5: =#REF! -> #REF! | T5: =#REF! -> #REF! | V5: =#REF! -> #REF! | W5: =#REF! -> #REF! | Y5: =#REF! -> #REF! | Z5: =#REF! -> #REF! | AB5: =#REF! -> #REF! | AC5: =#REF! -> #REF! | AE5: =#REF! -> #REF! | AF5: =#REF! -> #REF! | AH5: =#REF! -> #REF! | AI5: =#REF! -> #REF! | AK5: =#REF! -> #REF! | AL5: =#REF! -> #REF! | AN5: =#REF! -> #REF! | AO5: =#REF! -> #REF! | AQ5: =#REF! -> #REF! | AR5: =#REF! -> #REF! | AT5: =#REF! -> #REF! | AU5: =#REF! -> #REF! | AW5: =#REF! -> #REF! | AX5: =#REF! -> #REF! | AZ5: =#REF! -> #REF! | BA5: =#REF! -> #REF! | BC5: =#REF! -> #REF! | BD5: =#REF! -> #REF! | BF5: =#REF! -> #REF! | BG5: =#REF! -> #REF! | BI5: =#REF! -> #REF! | BJ5: =#REF! -> #REF! | BL5: =#REF! -> #REF! | BM5: =#REF! -> #REF!
A6: .
A7: Bäte | B7: H1 CEO | C7: 1 | D7: Allianz SE, Allianz Europe | E7: Shared Services | F7: 1 | G7: AZSE | H7: Allianz SE | J7: =#REF! -> #REF! | K7: =#REF! -> #REF! | Y7: =#REF! -> #REF! | Z7: =#REF! -> #REF! | AB7: =#REF! -> #REF! | AC7: =#REF! -> #REF! | BI7: =#REF! -> #REF! | BJ7: =#REF! -> #REF!
A8: . | F8: ∑ | G8: ∑ | H8: 1 | J8: =SUM(J7) -> #REF! | K8: =SUM(K7) -> #REF! | Y8: =#REF! -> #REF! | Z8: =#REF! -> #REF! | AB8: =#REF! -> #REF! | AC8: =#REF! -> #REF! | BB8: 0 | BE8: 0 | BI8: =#REF! -> #REF! | BJ8: =#REF! -> #REF!
A9: . | Y9: =#REF! -> #REF! | Z9: =#REF! -> #REF! | AB9: =#REF! -> #REF! | AC9: =#REF! -> #REF! | BI9: =#REF! -> #REF! | BJ9: =#REF! -> #REF!
A10: Thallinger | B10: H3 Investments Management | C10: 2 | D10: Allianz Investment | E10: Shared Services | F10: 2 | G10: ADEUS | H10: ADEUS Aktienregister-Service-GmbH | J10: =#REF! -> #REF! | K10: =#REF! -> #REF! | Y10: =#REF! -> #REF! | Z10: =#REF! -> #REF! | AB10: =#REF! -> #REF! | AC10: =#REF! -> #REF! | BI10: =#REF! -> #REF! | BJ10: =#REF! -> #REF!
E11: Europe 3 | F11: 3 | G11: AGL | H11: Allianz Global Life | J11: =#REF! -> #REF! | K11: =#REF! -> #REF! | Y11: =#REF! -> #REF! | Z11: =#REF! -> #REF! | AB11: =#REF! -> #REF! | AC11: =#REF! -> #REF! | BI11: =#REF! -> #REF! | BJ11: =#REF! -> #REF!
E12: Shared Services | F12: 4 | G12: AIM | H12: Allianz Investment Management (AIM) | J12: =#REF! -> #REF! | K12: =#REF! -> #REF! | Y12: =#REF! -> #REF! | Z12: =#REF! -> #REF! | AB12: =#REF! -> #REF! | AC12: =#REF! -> #REF! | BI12: =#REF! -> #REF! | BJ12: =#REF! -> #REF!
E13: Shared Services | F13: 5 | G13: ARE | H13: Allianz Real Estate (ARE) | J13: =#REF! -> #REF! | K13: =#REF! -> #REF! | Y13: =#REF! -> #REF! | Z13: =#REF! -> #REF! | AB13: =#REF! -> #REF! | AC13: =#REF! -> #REF! | BI13: =#REF! -> #REF! | BJ13: =#REF! -> #REF!
E14: Shared Services | F14: 6 | G14: IDS | H14: Investment Data Services (IDS) | J14: =#REF! -> #REF! | K14: =#REF! -> #REF! | Y14: =#REF! -> #REF! | Z14: =#REF! -> #REF! | AB14: =#REF! -> #REF! | AC14: =#REF! -> #REF! | BI14: =#REF! -> #REF! | BJ14: =#REF! -> #REF!
A15: . | F15: ∑ | G15: ∑ | H15: 5 | J15: =SUM(J10:J14) -> #REF! | K15: =SUM(K10:K14) -> #REF! | Y15: =#REF! -> #REF! | Z15: =#REF! -> #REF! | AB15: =#REF! -> #REF! | AC15: =#REF! -> #REF! | BB15: 0 | BE15: 0 | BI15: =#REF! -> #REF! | BJ15: =#REF! -> #REF!
A16: . | Y16: =#REF! -> #REF! | Z16: =#REF! -> #REF! | AB16: =#REF! -> #REF! | AC16: =#REF! -> #REF! | BI16: =#REF! -> #REF! | BJ16: =#REF! -> #REF!
A17: Mascher | B17: H4 Operations | C17: 3 | D17: Allianz Technology | E17: AZ Technology | F17: 7 | G17: AMOS | H17: Allianz Technology | J17: =#REF! -> #REF! | K17: =#REF! -> #REF! | Y17: =#REF! -> #REF! | Z17: =#REF! -> #REF! | AB17: =#REF! -> #REF! | AC17: =#REF! -> #REF! | BI17: =#REF! -> #REF! | BJ17: =#REF! -> #REF!
A18: . | F18: ∑ | G18: ∑ | H18: 1 | J18: =SUM(J17) -> #REF! | K18: =SUM(K17) -> #REF! | Y18: =#REF! -> #REF! | Z18: =#REF! -> #REF! | AB18: =#REF! -> #REF! | AC18: =#REF! -> #REF! | BB18: 0 | BE18: 0 | BI18: =#REF! -> #REF! | BJ18: =#REF! -> #REF!
A19: . | Y19: =#REF! -> #REF! | Z19: =#REF! -> #REF! | AB19: =#REF! -> #REF! | AC19: =#REF! -> #REF! | BI19: =#REF! -> #REF! | BJ19: =#REF! -> #REF!
A20: Balbinot | B20: H5 Insurance Western & Southern Europe, AZAP | C20: 4 | D20: AZAP | E20: AZAP | F20: 8 | G20: CNPC | H20: Allianz China - P&C | J20: =#REF! -> #REF! | K20: =#REF! -> #REF! | Y20: =#REF! -> #REF! | Z20: =#REF! -> #REF! | AB20: =#REF! -> #REF! | AC20: =#REF! -> #REF! | BI20: =#REF! -> #REF! | BJ20: =#REF! -> #REF!
B21: H2 Finance, Controlling, Risk | E21: AZAP | F21: 9 | G21: CNH | H21: Allianz China - Holding | Y21: =#REF! -> #REF! | Z21: =#REF! -> #REF! | AB21: =#REF! -> #REF! | AC21: =#REF! -> #REF! | BI21: =#REF! -> #REF! | BJ21: =#REF! -> #REF!
B22: H2 Finance, Controlling, Risk | E22: AZAP | F22: 10 | G22: ID | H22: Allianz Indonesia | Y22: =#REF! -> #REF! | Z22: =#REF! -> #REF! | AB22: =#REF! -> #REF! | AC22: =#REF! -> #REF! | BI22: =#REF! -> #REF! | BJ22: =#REF! -> #REF!
B23: H2 Finance, Controlling, Risk | E23: AZAP | F23: 11 | G23: JPLH | H23: Allianz Japan - Life | Y23: =#REF! -> #REF! | Z23: =#REF! -> #REF! | AB23: =#REF! -> #REF! | AC23: =#REF! -> #REF! | BI23: =#REF! -> #REF! | BJ23: =#REF! -> #REF!
B24: H2 Finance, Controlling, Risk | E24: AZAP | F24: 12 | G24: LAPC | H24: Allianz Laos | Y24: =#REF! -> #REF! | Z24: =#REF! -> #REF! | AB24: =#REF! -> #REF! | AC24: =#REF! -> #REF! | BI24: =#REF! -> #REF! | BJ24: =#REF! -> #REF!
B25: H2 Finance, Controlling, Risk | E25: AZAP | F25: 13 | G25: MY | H25: Allianz Malaysia | Y25: =#REF! -> #REF! | Z25: =#REF! -> #REF! | AB25: =#REF! -> #REF! | AC25: =#REF! -> #REF! | BI25: =#REF! -> #REF! | BJ25: =#REF! -> #REF!
B26: H2 Finance, Controlling, Risk | E26: AZAP | F26: 14 | G26: PH | H26: Allianz Philippine - L&H | Y26: =#REF! -> #REF! | Z26: =#REF! -> #REF! | AB26: =#REF! -> #REF! | AC26: =#REF! -> #REF! | BI26: =#REF! -> #REF! | BJ26: =#REF! -> #REF!
B27: H2 Finance, Controlling, Risk | E27: AZAP | F27: 15 | G27: LK | H27: Allianz Sri Lanka | Y27: =#REF! -> #REF! | Z27: =#REF! -> #REF! | AB27: =#REF! -> #REF! | AC27: =#REF! -> #REF! | BI27: =#REF! -> #REF! | BJ27: =#REF! -> #REF!
B28: H2 Finance, Controlling, Risk | E28: AZAP | F28: 16 | G28: AS | H28: Allianz Singapore | Y28: =#REF! -> #REF! | Z28: =#REF! -> #REF! | AB28: =#REF! -> #REF! | AC28: =#REF! -> #REF! | BI28: =#REF! -> #REF! | BJ28: =#REF! -> #REF!
B29: H2 Finance, Controlling, Risk | E29: AZAP | F29: 17 | G29: TWL | H29: Allianz Taiwan - Life | Y29: =#REF! -> #REF! | Z29: =#REF! -> #REF! | AB29: =#REF! -> #REF! | AC29: =#REF! -> #REF! | BI29: =#REF! -> #REF! | BJ29: =#REF! -> #REF!
B30: H2 Finance, Controlling, Risk | E30: AZAP | F30: 18 | G30: TH | H30: Allianz Thailand | Y30: =#REF! -> #REF! | Z30: =#REF! -> #REF! | AB30: =#REF! -> #REF! | AC30: =#REF! -> #REF! | BI30: =#REF! -> #REF! | BJ30: =#REF! -> #REF!
B31: H2 Finance, Controlling, Risk | E31: AZAP | F31: 19 | G31: FIN | H31: FinOS - Holding | Y31: =#REF! -> #REF! | Z31: =#REF! -> #REF! | AB31: =#REF! -> #REF! | AC31: =#REF! -> #REF! | BI31: =#REF! -> #REF! | BJ31: =#REF! -> #REF!
B32: H2 Finance, Controlling, Risk | F32: ∑ | G32: ∑ | H32: 12 | J32: =SUM(J20:J31) -> #REF! | K32: =SUM(K20:K31) -> #REF! | Y32: =#REF! -> #REF! | Z32: =#REF! -> #REF! | AB32: =#REF! -> #REF! | AC32: =#REF! -> #REF! | BB32: 0 | BE32: 0 | BI32: =#REF! -> #REF! | BJ32: =#REF! -> #REF!
B33: H2 Finance, Controlling, Risk | C33: 5 | D33: Allianz Benelux | E33: Europe 2 | F33: 21 | G33: BLX | H33: Allianz Benelux | J33: =#REF! -> #REF! | K33: =#REF! -> #REF! | Y33: =#REF! -> #REF! | Z33: =#REF! -> #REF! | AB33: =#REF! -> #REF! | AC33: =#REF! -> #REF! | BI33: =#REF! -> #REF! | BJ33: =#REF! -> #REF!
B34: H2 Finance, Controlling, Risk | C34: 6 | D34: Allianz France | E34: Europe 2 | F34: 22 | G34: FR | H34: Allianz France | J34: =#REF! -> #REF! | K34: =#REF! -> #REF! | Y34: =#REF! -> #REF! | Z34: =#REF! -> #REF! | AB34: =#REF! -> #REF! | AC34: =#REF! -> #REF! | BI34: =#REF! -> #REF! | BJ34: =#REF! -> #REF!
B35: H2 Finance, Controlling, Risk | C35: 7 | D35: Allianz Greece | E35: Europe 3 | F35: 23 | G35: GR | H35: Allianz Greece | J35: =#REF! -> #REF! | K35: =#REF! -> #REF! | Y35: =#REF! -> #REF! | Z35: =#REF! -> #REF! | AB35: =#REF! -> #REF! | AC35: =#REF! -> #REF! | BI35: =#REF! -> #REF! | BJ35: =#REF! -> #REF!
B36: H2 Finance, Controlling, Risk | C36: 8 | D36: Allianz Italy | E36: Europe 3 | F36: 24 | G36: IT | H36: Allianz Italy | J36: =#REF! -> #REF! | K36: =#REF! -> #REF! | Y36: =#REF! -> #REF! | Z36: =#REF! -> #REF! | AB36: =#REF! -> #REF! | AC36: =#REF! -> #REF! | BI36: =#REF! -> #REF! | BJ36: =#REF! -> #REF!
B37: H2 Finance, Controlling, Risk | C37: 9 | D37: Allianz Turkey | E37: Europe 3 | F37: 25 | G37: TR | H37: Allianz Turkey | J37: =#REF! -> #REF! | K37: =#REF! -> #REF! | Y37: =#REF! -> #REF! | Z37: =#REF! -> #REF! | AB37: =#REF! -> #REF! | AC37: =#REF! -> #REF! | BI37: =#REF! -> #REF! | BJ37: =#REF! -> #REF!
A38: . | F38: ∑ | G38: ∑ | H38: 17 | J38: =SUM(J32:J37) -> #REF! | K38: =SUM(K32:K37) -> #REF! | Y38: =#REF! -> #REF! | Z38: =#REF! -> #REF! | AB38: =#REF! -> #REF! | AC38: =#REF! -> #REF! | BB38: 0 | BE38: 0 | BI38: =#REF! -> #REF! | BJ38: =#REF! -> #REF!
A39: . | Y39: =#REF! -> #REF! | Z39: =#REF! -> #REF! | AB39: =#REF! -> #REF! | AC39: =#REF! -> #REF! | BI39: =#REF! -> #REF! | BJ39: =#REF! -> #REF!
A40: Theis | B40: H7 Insurance German Speaking Countries & CEE | C40: 10 | D40: Allianz Germany | E40: Europe 1 | F40: 26 | G40: AZD | H40: Allianz Germany | J40: =#REF! -> #REF! | K40: =#REF! -> #REF! | Y40: =#REF! -> #REF! | Z40: =#REF! -> #REF! | AB40: =#REF! -> #REF! | AC40: =#REF! -> #REF! | BI40: =#REF! -> #REF! | BJ40: =#REF! -> #REF!
...

Sheet Plan view
B1: IT Security Investment Initiative
B2: Progress KPI plan view
B4: Focus Area | C4: # | D4: Measure | E4: Progress KPIs | F4: Baseline 01.07.2021 | G4: =Overview!N5 -> Actuals 24.09.21 | H4: Target 31.12.2021 | J4: Plan 09/2021 | K4: Plan 10/2021 | L4: Plan 11/2021 | M4: Plan 12/2021
B5: Slow Down Hackers | C5: KPI(1) | D5: M274 | E5: # of scenarios tested | F5: 0 | G5: 0 | H5: 4 | J5: ='M274'!$R$4 -> 0 | K5: ='M274'!$S$4 -> 0 | L5: ='M274'!$T$4 -> 2 | M5: ='M274'!$U$4 -> 4
C6: KPI (2) | D6: M275 | E6: # of Security Consultations | F6: 0 | G6: 0 | H6: 10 | J6: ='M275'!$R$4 -> 2 | K6: ='M275'!$S$4 -> 5 | L6: ='M275'!$T$4 -> 8 | M6: ='M275'!$U$4 -> 10
C7: KPI (3) | D7: M276 | E7: # of application penetration tests performed | F7: 0 | G7: 1 | H7: 30 | J7: ='M276'!$R$4 -> 2 | K7: ='M276'!$S$4 -> 10 | L7: ='M276'!$T$4 -> 20 | M7: ='M276'!$U$4 -> 30
C8: KPI (4) | D8: M277 | E8: # of event propagation from the source to the SIEM response | F8: 0 | G8: 0 | H8: 3 | J8: ='M277'!$R$4 -> 1 | K8: ='M277'!$S$4 -> 2 | L8: ='M277'!$T$4 -> 3 | M8: ='M277'!$U$4 -> 3
C9: KPI (5) | D9: M278 | E9: # of artefacts completed | F9: 0 | G9: 0 | H9: 5 | J9: ='M278'!$R$4 -> 0 | K9: ='M278'!$S$4 -> 2 | L9: ='M278'!$T$4 -> 4 | M9: ='M278'!$U$4 -> 5
C10: KPI (6) | D10: M279 | E10: # of artefacts achieved and requirements analyzed | F10: 0 | G10: 1 | H10: 9 | J10: ='M279'!$R$4 -> 2 | K10: ='M279'!$S$4 -> 3 | L10: ='M279'!$T$4 -> 5 | M10: ='M279'!$U$4 -> 9
C11: KPI (7) | D11: M302 | E11: # of reached milestones | F11: 0 | G11: 0 | H11: 5 | J11: ='M302'!$R$4 -> 0 | K11: ='M302'!$S$4 -> 2 | L11: ='M302'!$T$4 -> 3 | M11: ='M302'!$U$4 -> 5
B12: 2. Increase detection | C12: KPI (8) | D12: M280 | E12: # of new generation ADH deployment | F12: 0 | G12: 0 | H12: 10 | J12: ='M280'!$R$4 -> 0 | K12: ='M280'!$S$4 -> 0 | L12: ='M280'!$T$4 -> 1 | M12: ='M280'!$U$4 -> 10
C13: KPI (9) | D13: M281 | E13: # of DNS Server logs consumed | F13: 0 | G13: 0 | H13: 2 | J13: ='M281'!$R$4 -> 0 | K13: ='M281'!$S$4 -> 0 | L13: ='M281'!$T$4 -> 1 | M13: ='M281'!$U$4 -> 2 | P13: 1
C14: KPI (10) | D14: M282 | E14: # of DCs and endpoints covered with deception | F14: 0 | G14: 0 | H14: 6 | J14: ='M282'!$R$4 -> 0 | K14: ='M282'!$S$4 -> 2 | L14: ='M282'!$T$4 -> 4 | M14: ='M282'!$U$4 -> 6
C15: KPI (11) | D15: M283 | E15: # of implemented cloud use cases | F15: 0 | G15: 1 | H15: 10 | J15: ='M283'!$R$4 -> 0 | K15: ='M283'!$S$4 -> 2 | L15: ='M283'!$T$4 -> 6 | M15: ='M283'!$U$4 -> 10
C16: KPI (12) | D16: M284 | E16: # of integrations or play books implemented | F16: 0 | G16: 4 | H16: 8 | J16: ='M284'!$R$4 -> 2 | K16: ='M284'!$S$4 -> 4 | L16: ='M284'!$T$4 -> 6 | M16: ='M284'!$U$4 -> 8
C17: KPI (13) | D17: M285 | E17: # of business critical applications moved to Enforce-Mode | F17: 0 | G17: 2 | H17: 30 | J17: ='M285'!$R$4 -> 8 | K17: ='M285'!$S$4 -> 15 | L17: ='M285'!$T$4 -> 25 | M17: ='M285'!$U$4 -> 30
C18: KPI (14) | D18: M286 | E18: # of Reporting User Stories designed and User Stories implemented | F18: 0 | G18: 1 | H18: 12 | J18: ='M286'!$R$4 -> 4 | K18: ='M286'!$S$4 -> 6 | L18: ='M286'!$T$4 -> 8 | M18: ='M286'!$U$4 -> 12
B19: 3. Reduce damage | C19: KPI (15) | D19: M287 | E19: # of OEs covered with Qualys agents on clients | F19: 0 | G19: 1 | H19: 20 | J19: ='M287'!$R$4 -> 6 | K19: ='M287'!$S$4 -> 18 | L19: ='M287'!$T$4 -> 42 | M19: ='M287'!$U$4 -> 58
C20: KPI (16) | D20: M288 | E20: # of reached milestones | F20: 0 | G20: 1 | H20: 4 | J20: ='M288'!$R$4 -> 1 | K20: ='M288'!$S$4 -> 1 | L20: ='M288'!$T$4 -> 2 | M20: ='M288'!$U$4 -> 4
C21: KPI (17) | D21: M289 | E21: # of users rolled-out to password manager service | F21: 0 | G21: 0 | H21: 1000 | J21: ='M289'!$R$4 -> 0 | K21: ='M289'!$S$4 -> 0 | L21: ='M289'!$T$4 -> 0 | M21: ='M289'!$U$4 -> 1000
C22: KPI (18) | D22: M290 | E22: # of Service design documents for future CAD service developed | F22: 0 | G22: 4 | H22: 6 | J22: ='M290'!$R$4 -> 6 | K22: ='M290'!$S$4 -> 6 | L22: ='M290'!$T$4 -> 6 | M22: ='M290'!$U$4 -> 6
C23: KPI (19) | D23: M291 | E23: # of validate possible integrations | F23: 0 | G23: 0 | H23: 4 | J23: ='M291'!$R$4 -> 0 | K23: ='M291'!$S$4 -> 0 | L23: ='M291'!$T$4 -> 2 | M23: ='M291'!$U$4 -> 4
C24: KPI (20a) | D24: M301 | E24: # of Global Tier 0 Hosting Platform Design and APAC Pilot | F24: 0 | G24: 0 | H24: 8 | J24: =M301_a!$R$4 -> 0 | K24: =M301_a!$S$4 -> 0 | L24: =M301_a!$T$4 -> 4 | M24: =M301_a!$U$4 -> 8
C25: KPI (20b) | D25: M301 | E25: # of Local APAC units of Allianz Partners: Domain Controllers onboarded to Tier 0 Hosting Platform | F25: 0 | G25: 0 | H25: 4 | J25: =M301_b!$R$4 -> 0 | K25: =M301_b!$S$4 -> 0 | L25: =M301_b!$T$4 -> 2 | M25: =M301_b!$U$4 -> 4
B26: 4. Streamline compliance | C26: KPI (21) | D26: M292 | E26: # of reached artefacts | F26: 0 | G26: 0 | H26: 5 | J26: ='M292'!$R$4 -> 0 | K26: ='M292'!$S$4 -> 1 | L26: ='M292'!$T$4 -> 3 | M26: ='M292'!$U$4 -> 5
C27: KPI (22) | D27: M293 | E27: # of Toxic Asset Dashboard including client IT asset data (e.g. AVC, AMC, fat client, smart mobile de-vices) for minimum of 25 OEs | F27: 0 | G27: 0 | H27: 25 | J27: ='M293'!$R$4 -> 0 | K27: ='M293'!$S$4 -> 0 | L27: ='M293'!$T$4 -> 0 | M27: ='M293'!$U$4 -> 73
C28: KPI (23) | D28: M294 | E28: # of reached milestones | F28: 0 | G28: 0 | H28: 5 | J28: ='M294'!$R$4 -> 2 | K28: ='M294'!$S$4 -> 2 | L28: ='M294'!$T$4 -> 3 | M28: ='M294'!$U$4 -> 5
C29: KPI (24) | D29: M295 | E29: # of KPI + SLA vetting draft for 6 Security Services | F29: 0 | G29: 0 | H29: 12 | J29: ='M295'!$R$4 -> 1 | K29: ='M295'!$S$4 -> 4 | L29: ='M295'!$T$4 -> 9 | M29: ='M295'!$U$4 -> 12
B30: 5. Build Security org/skills | C30: KPI (25) | D30: M296 | E30: # of OEs evaluated within BitSight financial model | F30: 0 | G30: 0 | H30: 10 | J30: ='M296'!$R$4 -> 0 | K30: ='M296'!$S$4 -> 9 | L30: ='M296'!$T$4 -> 19 | M30: ='M296'!$U$4 -> 19
C31: KPI (26) | D31: M297 | E31: # of learning nuggets and OE dashboards created | F31: 0 | G31: 0 | H31: 10 | J31: ='M297'!$R$4 -> 0 | K31: ='M297'!$S$4 -> 1 | L31: ='M297'!$T$4 -> 3 | M31: ='M297'!$U$4 -> 10
C32: KPI (27) | D32: M298 | E32: # of reached artefacts | F32: 0 | G32: 0 | H32: 3 | J32: ='M298'!$R$4 -> 0 | K32: ='M298'!$S$4 -> 0 | L32: ='M298'!$T$4 -> 1 | M32: ='M298'!$U$4 -> 3
C33: KPI (28) | D33: M299 | E33: # of architectural documents (e.g. pattern / analysis / methodology) published | F33: 0 | G33: 0 | H33: 7 | J33: ='M299'!$R$4 -> 0 | K33: ='M299'!$S$4 -> 1 | L33: ='M299'!$T$4 -> 4 | M33: ='M299'!$U$4 -> 7
C34: KPI (29) | D34: M300 | E34: # of high qualitative metrics for ROI | F34: 0 | G34: 0 | H34: 5 | J34: ='M300'!$R$4 -> 0 | K34: ='M300'!$S$4 -> 0 | L34: ='M300'!$T$4 -> 0 | M34: ='M300'!$U$4 -> 5
B36: - confidential -

Sheet M274
H1: Focus Area | J1: Slow down hackers | S1: All yellow marked columns to be filled out
A2: IT Security Initiative | J2: M274 | K2: #REF! | R2: Please fill in your monthly split of planned KPI target values (accumulated plan). Please leave a comment: In which CW will you report your first progress?
A3: =Overview!A3 -> Progress KPI Reporting 2021 | J3: ='Plan view'!E5 -> # of scenarios tested
J4: =J8 -> 4 | K4: =K8 -> 0 | M4: =M8 -> 0 | N4: =N8 -> 0 | O4: =O8 -> 0 | P4: =P8 -> 0 | R4: =R8 -> 0 | S4: =S8 -> 0 | T4: =T8 -> 2 | U4: =U8 -> 4
J5: Target 31.12.21 | K5: Actuals 24.09.21 | M5: Actuals 17.09.21 | N5: Actuals 10.09.21 | O5: Actuals 03.09.21 | P5: Baseline 01.07.21 | R5: Plan 09/2021 | S5: Plan 10/2021 | T5: Plan 11/2021 | U5: Plan 12/2021 | W5: Comments
A6: .
J8: ='Plan view'!H5 -> 4 | K8: 0 | M8: 0 | N8: 0 | O8: 0 | P8: ='Plan view'!F5 -> 0 | R8: 0 | S8: 0 | T8: 2 | U8: 4 | W8: First KPI progress planned for CW 45
W9: First KPI progress planned for CW 45
W10: First KPI progress planned for CW 45
W11: First KPI progress planned for CW 45
W12: First KPI progress planned for CW 45
W13: First KPI progress planned for CW 45
W14: First KPI progress planned for CW 45
W15: First KPI progress planned for CW 45
W16: First KPI progress planned for CW 45
W17: First KPI progress planned for CW 45
W18: First KPI progress planned for CW 45
W19: First KPI progress planned for CW 45

Sheet M275
H1: Focus Area | J1: Slow down hackers | S1: All yellow marked columns to be filled out
A2: IT Security Initiative | J2: M275 | K2: #REF! | R2: Please fill in your monthly split of planned KPI target values (accumulated plan). Please leave a comment: In which CW will you report your first progress?
A3: =Overview!A3 -> Progress KPI Reporting 2021 | J3: ='Plan view'!E6 -> # of Security Consultations
J4: =J8 -> 10 | K4: =K8 -> 0 | M4: =M8 -> 0 | N4: =N8 -> 0 | O4: =O8 -> 0 | P4: =P8 -> 0 | R4: =R8 -> 2 | S4: =S8 -> 5 | T4: =T8 -> 8 | U4: =U8 -> 10
J5: Target 31.12.21 | K5: Actuals 24.09.21 | M5: Actuals 17.09.21 | N5: Actuals 10.09.21 | O5: Actuals 03.09.21 | P5: Baseline 01.07.21 | R5: Plan 09/2021 | S5: Plan 10/2021 | T5: Plan 11/2021 | U5: Plan 12/2021 | W5: Comments
A6: .
J8: ='Plan view'!H6 -> 10 | K8: 0 | M8: 0 | N8: 0 | O8: 0 | P8: ='Plan view'!$F6 -> 0 | R8: 2 | S8: 5 | T8: 8 | U8: 10 | W8: First progress will be reported in CW 39.
W9: First progress will be reported in CW 39.
W10: First progress will be reported in CW 39.
W11: First progress will be reported in CW 39.
W12: First progress will be reported in CW 39.
W13: First progress will be reported in CW 39.
W14: First progress will be reported in CW 39.
W15: First progress will be reported in CW 39.
W16: First progress will be reported in CW 39.
W17: First progress will be reported in CW 39.
W18: First progress will be reported in CW 39.
W19: First progress will be reported in CW 39.

Sheet M276
H1: Focus Area | J1: Slow down hackers | S1: All yellow marked columns to be filled out
A2: IT Security Initiative | J2: M276 | K2: #REF! | R2: Please fill in your monthly split of planned KPI target values (accumulated plan). Please leave a comment: In which CW will you report your first progress?
A3: =Overview!A3 -> Progress KPI Reporting 2021 | J3: ='Plan view'!E7 -> # of application penetration tests performed
J4: =J8 -> 30 | K4: =K8 -> 1 | M4: =M8 -> 1 | N4: =N8 -> 0 | O4: =O8 -> 0 | P4: =P8 -> 0 | R4: =R8 -> 2 | S4: =S8 -> 10 | T4: =T8 -> 20 | U4: =U8 -> 30
J5: Target 31.12.21 | K5: Actuals 24.09.21 | M5: Actuals 17.09.21 | N5: Actuals 10.09.21 | O5: Actuals 03.09.21 | P5: Baseline 01.07.21 | R5: Plan 09/2021 | S5: Plan 10/2021 | T5: Plan 11/2021 | U5: Plan 12/2021 | W5: Comments
A6: .
J8: ='Plan view'!$H7 -> 30 | K8: 1 | M8: 1 | N8: 0 | O8: 0 | P8: ='Plan view'!$F7 -> 0 | R8: 2 | S8: 10 | T8: 20 | U8: 30 | W8: First Progress expected in CW 37; First Penetration Test is ongoing, second should start next week.
W9: First Progress expected in CW 37; First Penetration Test is ongoing, second should start next week.
W10: First Progress expected in CW 37; First Penetration Test is ongoing, second should start next week.
W11: First Progress expected in CW 37; First Penetration Test is ongoing, second should start next week.
W12: First Progress expected in CW 37; First Penetration Test is ongoing, second should start next week.
W13: First Progress expected in CW 37; First Penetration Test is ongoing, second should start next week.
W14: First Progress expected in CW 37; First Penetration Test is ongoing, second should start next week.
W15: First Progress expected in CW 37; First Penetration Test is ongoing, second should start next week.
W16: First Progress expected in CW 37; First Penetration Test is ongoing, second should start next week.
W17: First Progress expected in CW 37; First Penetration Test is ongoing, second should start next week.
W18: First Progress expected in CW 37; First Penetration Test is ongoing, second should start next week.
W19: First Progress expected in CW 37; First Penetration Test is ongoing, second should start next week.

Sheet M277
H1: Focus Area | J1: Slow down hackers | S1: All yellow marked columns to be filled out
A2: IT Security Initiative | J2: M277 | K2: #REF! | R2: Please fill in your monthly split of planned KPI target values (accumulated plan). Please leave a comment: In which CW will you report your first progress?
A3: =Overview!A3 -> Progress KPI Reporting 2021 | J3: ='Plan view'!E8 -> # of event propagation from the source to the SIEM response
J4: =J8 -> 3 | K4: =K8 -> 0 | M4: =M8 -> 0 | N4: =N8 -> 0 | O4: =O8 -> 0 | P4: =P8 -> 0 | R4: =R8 -> 1 | S4: =S8 -> 2 | T4: =T8 -> 3 | U4: =U8 -> 3
J5: Target 31.12.21 | K5: Actuals 24.09.21 | M5: Actuals 17.09.21 | N5: Actuals 10.09.21 | O5: Actuals 03.09.21 | P5: Baseline 01.07.21 | R5: Plan 09/2021 | S5: Plan 10/2021 | T5: Plan 11/2021 | U5: Plan 12/2021 | W5: Comments
A6: .
J8: ='Plan view'!$H8 -> 3 | K8: 0 | M8: 0 | N8: 0 | O8: 0 | P8: ='Plan view'!$F8 -> 0 | R8: 1 | S8: 2 | T8: 3 | U8: 3 | W8: First report will be in CW: 39 KPI description of stages: #1: Events gathered from source (AD/AAD) #2: Events correlated on the Cygna Auditor Platform #3: Events forwarded to ACDC and observed on the SIEM.
W9: First report will be in CW: 39 KPI description of stages: #1: Events gathered from source (AD/AAD) #2: Events correlated on the Cygna Auditor Platform #3: Events forwarded to ACDC and observed on the SIEM.
W10: First report will be in CW: 39 KPI description of stages: #1: Events gathered from source (AD/AAD) #2: Events correlated on the Cygna Auditor Platform #3: Events forwarded to ACDC and observed on the SIEM.
W11: First report will be in CW: 39 KPI description of stages: #1: Events gathered from source (AD/AAD) #2: Events correlated on the Cygna Auditor Platform #3: Events forwarded to ACDC and observed on the SIEM.
W12: First report will be in CW: 39 KPI description of stages: #1: Events gathered from source (AD/AAD) #2: Events correlated on the Cygna Auditor Platform #3: Events forwarded to ACDC and observed on the SIEM.
W13: First report will be in CW: 39 KPI description of stages: #1: Events gathered from source (AD/AAD) #2: Events correlated on the Cygna Auditor Platform #3: Events forwarded to ACDC and observed on the SIEM.
W14: First report will be in CW: 39 KPI description of stages: #1: Events gathered from source (AD/AAD) #2: Events correlated on the Cygna Auditor Platform #3: Events forwarded to ACDC and observed on the SIEM.
W15: First report will be in CW: 39 KPI description of stages: #1: Events gathered from source (AD/AAD) #2: Events correlated on the Cygna Auditor Platform #3: Events forwarded to ACDC and observed on the SIEM.
W16: First report will be in CW: 39 KPI description of stages: #1: Events gathered from source (AD/AAD) #2: Events correlated on the Cygna Auditor Platform #3: Events forwarded to ACDC and observed on the SIEM.
W17: First report will be in CW: 39 KPI description of stages: #1: Events gathered from source (AD/AAD) #2: Events correlated on the Cygna Auditor Platform #3: Events forwarded to ACDC and observed on the SIEM.
W18: First report will be in CW: 39 KPI description of stages: #1: Events gathered from source (AD/AAD) #2: Events correlated on the Cygna Auditor Platform #3: Events forwarded to ACDC and observed on the SIEM.
W19: First report will be in CW: 39 KPI description of stages: #1: Events gathered from source (AD/AAD) #2: Events correlated on the Cygna Auditor Platform #3: Events forwarded to ACDC and observed on the SIEM.

Sheet M278
H1: Focus Area | J1: Slow down hackers | S1: All yellow marked columns to be filled out
A2: IT Security Initiative | J2: M278 | K2: #REF! | R2: Please fill in your monthly split of planned KPI target values (accumulated plan). Please leave a comment: In which CW will you report your first progress?
A3: =Overview!A3 -> Progress KPI Reporting 2021 | J3: ='Plan view'!E9 -> # of artefacts completed
J4: =J8 -> 5 | K4: =K8 -> 0 | M4: =M8 -> 0 | N4: =N8 -> 0 | O4: =O8 -> 0 | P4: =P8 -> 0 | R4: =R8 -> 0 | S4: =S8 -> 2 | T4: =T8 -> 4 | U4: =U8 -> 5
J5: Target 31.12.21 | K5: Actuals 24.09.21 | M5: Actuals 17.09.21 | N5: Actuals 10.09.21 | O5: Actuals 03.09.21 | P5: Baseline 01.07.21 | R5: Plan 09/2021 | S5: Plan 10/2021 | T5: Plan 11/2021 | U5: Plan 12/2021 | W5: Comments
A6: .
J8: ='Plan view'!$H9 -> 5 | K8: 0 | M8: 0 | N8: 0 | O8: 0 | P8: ='Plan view'!$F9 -> 0 | R8: 0 | S8: 2 | T8: 4 | U8: 5

Sheet M279
H1: Focus Area | J1: Slow down hackers | S1: All yellow marked columns to be filled out
A2: IT Security Initiative | J2: M279 | K2: #REF! | R2: Please fill in your monthly split of planned KPI target values (accumulated plan). Please leave a comment: In which CW will you report your first progress?
A3: =Overview!A3 -> Progress KPI Reporting 2021 | J3: ='Plan view'!E10 -> # of artefacts achieved and requirements analyzed
J4: =J8 -> 9 | K4: =K8 -> 1 | M4: =M8 -> 1 | N4: =N8 -> 1 | O4: =O8 -> 0 | P4: =P8 -> 0 | R4: =R8 -> 2 | S4: =S8 -> 3 | T4: =T8 -> 5 | U4: =U8 -> 9
J5: Target 31.12.21 | K5: Actuals 24.09.21 | M5: Actuals 17.09.21 | N5: Actuals 10.09.21 | O5: Actuals 03.09.21 | P5: Baseline 01.07.21 | R5: Plan 09/2021 | S5: Plan 10/2021 | T5: Plan 11/2021 | U5: Plan 12/2021 | W5: Comments
A6: .
J8: ='Plan view'!$H10 -> 9 | K8: 1 | M8: 1 | N8: 1 | O8: 0 | P8: ='Plan view'!$F10 -> 0 | R8: 2 | S8: 3 | T8: 5 | U8: 9 | W8: Number 9 is satisfied when 5 project artifacts are done and vendors are evaluated from atlast 4 perspectives. KPI descriptions are as follow: 1) Requirment identification 2) Vendor selection 3) Architecture design 4) Proof of Concept 5) Integration possibility with SIEM 6) long term cost 7) Functionality 8) Integration 9) Analytics power
W9: Number 9 is satisfied when 5 project artifacts are done and vendors are evaluated from atlast 4 perspectives. KPI descriptions are as follow: 1) Requirment identification 2) Vendor selection 3) Architecture design 4) Proof of Concept 5) Integration possibility with SIEM 6) long term cost 7) Functionality 8) Integration 9) Analytics power
W10: Number 9 is satisfied when 5 project artifacts are done and vendors are evaluated from atlast 4 perspectives. KPI descriptions are as follow: 1) Requirment identification 2) Vendor selection 3) Architecture design 4) Proof of Concept 5) Integration possibility with SIEM 6) long term cost 7) Functionality 8) Integration 9) Analytics power
W11: Number 9 is satisfied when 5 project artifacts are done and vendors are evaluated from atlast 4 perspectives. KPI descriptions are as follow: 1) Requirment identification 2) Vendor selection 3) Architecture design 4) Proof of Concept 5) Integration possibility with SIEM 6) long term cost 7) Functionality 8) Integration 9) Analytics power
W12: Number 9 is satisfied when 5 project artifacts are done and vendors are evaluated from atlast 4 perspectives. KPI descriptions are as follow: 1) Requirment identification 2) Vendor selection 3) Architecture design 4) Proof of Concept 5) Integration possibility with SIEM 6) long term cost 7) Functionality 8) Integration 9) Analytics power
W13: Number 9 is satisfied when 5 project artifacts are done and vendors are evaluated from atlast 4 perspectives. KPI descriptions are as follow: 1) Requirment identification 2) Vendor selection 3) Architecture design 4) Proof of Concept 5) Integration possibility with SIEM 6) long term cost 7) Functionality 8) Integration 9) Analytics power
W14: Number 9 is satisfied when 5 project artifacts are done and vendors are evaluated from atlast 4 perspectives. KPI descriptions are as follow: 1) Requirment identification 2) Vendor selection 3) Architecture design 4) Proof of Concept 5) Integration possibility with SIEM 6) long term cost 7) Functionality 8) Integration 9) Analytics power
W15: Number 9 is satisfied when 5 project artifacts are done and vendors are evaluated from atlast 4 perspectives. KPI descriptions are as follow: 1) Requirment identification 2) Vendor selection 3) Architecture design 4) Proof of Concept 5) Integration possibility with SIEM 6) long term cost 7) Functionality 8) Integration 9) Analytics power
W16: Number 9 is satisfied when 5 project artifacts are done and vendors are evaluated from atlast 4 perspectives. KPI descriptions are as follow: 1) Requirment identification 2) Vendor selection 3) Architecture design 4) Proof of Concept 5) Integration possibility with SIEM 6) long term cost 7) Functionality 8) Integration 9) Analytics power
W17: Number 9 is satisfied when 5 project artifacts are done and vendors are evaluated from atlast 4 perspectives. KPI descriptions are as follow: 1) Requirment identification 2) Vendor selection 3) Architecture design 4) Proof of Concept 5) Integration possibility with SIEM 6) long term cost 7) Functionality 8) Integration 9) Analytics power
W18: Number 9 is satisfied when 5 project artifacts are done and vendors are evaluated from atlast 4 perspectives. KPI descriptions are as follow: 1) Requirment identification 2) Vendor selection 3) Architecture design 4) Proof of Concept 5) Integration possibility with SIEM 6) long term cost 7) Functionality 8) Integration 9) Analytics power
W19: Number 9 is satisfied when 5 project artifacts are done and vendors are evaluated from atlast 4 perspectives. KPI descriptions are as follow: 1) Requirment identification 2) Vendor selection 3) Architecture design 4) Proof of Concept 5) Integration possibility with SIEM 6) long term cost 7) Functionality 8) Integration 9) Analytics power

Sheet M302
H1: Focus Area | J1: Slow down hackers | S1: All yellow marked columns to be filled out
A2: IT Security Initiative | J2: M302 | K2: #REF! | R2: Please fill in your monthly split of planned KPI target values (accumulated plan). Please leave a comment: In which CW will you report your first progress?
A3: =Overview!A3 -> Progress KPI Reporting 2021 | J3: ='Plan view'!E11 -> # of reached milestones
J4: =J8 -> 5 | K4: =K8 -> 0 | M4: =M8 -> 0 | N4: =N8 -> 0 | O4: =O8 -> 0 | P4: =P8 -> 0 | R4: =R8 -> 0 | S4: =S8 -> 2 | T4: =T8 -> 3 | U4: =U8 -> 5
J5: Target 31.12.21 | K5: Actuals 24.09.21 | M5: Actuals 17.09.21 | N5: Actuals 10.09.21 | O5: Actuals 03.09.21 | P5: Baseline 01.07.21 | R5: Plan 09/2021 | S5: Plan 10/2021 | T5: Plan 11/2021 | U5: Plan 12/2021 | W5: Comments
A6: .
J8: ='Plan view'!$H11 -> 5 | K8: 0 | M8: 0 | N8: 0 | O8: 0 | P8: ='Plan view'!$F11 -> 0 | R8: 0 | S8: 2 | T8: 3 | U8: 5

Sheet M280
H1: Focus Area | J1: Increase Detection | S1: All yellow marked columns to be filled out
A2: IT Security Initiative | J2: M280 | K2: #REF! | R2: Please fill in your monthly split of planned KPI target values (accumulated plan). Please leave a comment: In which CW will you report your first progress?
A3: =Overview!A3 -> Progress KPI Reporting 2021 | J3: ='Plan view'!E12 -> # of new generation ADH deployment
J4: =J8 -> 10 | K4: =K8 -> 0 | M4: =M8 -> 0 | N4: =N8 -> 0 | O4: =O8 -> 0 | P4: =P8 -> 0 | R4: =R8 -> 0 | S4: =S8 -> 0 | T4: =T8 -> 1 | U4: =U8 -> 10
J5: Target 31.12.21 | K5: Actuals 24.09.21 | M5: Actuals 17.09.21 | N5: Actuals 10.09.21 | O5: Actuals 03.09.21 | P5: Baseline 01.07.21 | R5: Plan 09/2021 | S5: Plan 10/2021 | T5: Plan 11/2021 | U5: Plan 12/2021 | W5: Comments
A6: .
J8: ='Plan view'!$H12 -> 10 | K8: 0 | M8: 0 | N8: 0 | O8: 0 | P8: ='Plan view'!$F12 -> 0 | R8: 0 | S8: 0 | T8: 1 | U8: 10 | W8: Main project work is to define architecture and set up pilot, rollout of new ADHs will be done in parallel, but deployment completion can only be done at project end following successful pilot.
W9: Main project work is to define architecture and set up pilot, rollout of new ADHs will be done in parallel, but deployment completion can only be done at project end following successful pilot.
W10: Main project work is to define architecture and set up pilot, rollout of new ADHs will be done in parallel, but deployment completion can only be done at project end following successful pilot.
W11: Main project work is to define architecture and set up pilot, rollout of new ADHs will be done in parallel, but deployment completion can only be done at project end following successful pilot.
W12: Main project work is to define architecture and set up pilot, rollout of new ADHs will be done in parallel, but deployment completion can only be done at project end following successful pilot.
W13: Main project work is to define architecture and set up pilot, rollout of new ADHs will be done in parallel, but deployment completion can only be done at project end following successful pilot.
W14: Main project work is to define architecture and set up pilot, rollout of new ADHs will be done in parallel, but deployment completion can only be done at project end following successful pilot.
W15: Main project work is to define architecture and set up pilot, rollout of new ADHs will be done in parallel, but deployment completion can only be done at project end following successful pilot.
W16: Main project work is to define architecture and set up pilot, rollout of new ADHs will be done in parallel, but deployment completion can only be done at project end following successful pilot.
W17: Main project work is to define architecture and set up pilot, rollout of new ADHs will be done in parallel, but deployment completion can only be done at project end following successful pilot.
W18: Main project work is to define architecture and set up pilot, rollout of new ADHs will be done in parallel, but deployment completion can only be done at project end following successful pilot.
W19: Main project work is to define architecture and set up pilot, rollout of new ADHs will be done in parallel, but deployment completion can only be done at project end following successful pilot.

Sheet M281
H1: Focus Area | J1: Increase Detection | S1: All yellow marked columns to be filled out
A2: IT Security Initiative | J2: M281 | K2: #REF! | R2: Please fill in your monthly split of planned KPI target values (accumulated plan). Please leave a comment: In which CW will you report your first progress?
A3: =Overview!A3 -> Progress KPI Reporting 2021 | J3: ='Plan view'!E13 -> # of DNS Server logs consumed
J4: =J8 -> 2 | K4: =K8 -> 0 | M4: =M8 -> 0 | N4: =N8 -> 0 | O4: =O8 -> 0 | P4: =P8 -> 0 | R4: =R8 -> 0 | S4: =S8 -> 0 | T4: =T8 -> 1 | U4: =U8 -> 2
J5: Target 31.12.21 | K5: Actuals 24.09.21 | M5: Actuals 17.09.21 | N5: Actuals 10.09.21 | O5: Actuals 03.09.21 | P5: Baseline 01.07.21 | R5: Plan 09/2021 | S5: Plan 10/2021 | T5: Plan 11/2021 | U5: Plan 12/2021 | W5: Comments
A6: .
J8: ='Plan view'!$H13 -> 2 | K8: 0 | M8: 0 | N8: 0 | O8: 0 | P8: ='Plan view'!$F8 -> 0 | R8: 0 | S8: 0 | T8: 1 | U8: 2

Sheet M282
H1: Focus Area | J1: Increase Detection | S1: All yellow marked columns to be filled out
A2: IT Security Initiative | J2: M282 | K2: #REF! | R2: Please fill in your monthly split of planned KPI target values (accumulated plan). Please leave a comment: In which CW will you report your first progress?
A3: =Overview!A3 -> Progress KPI Reporting 2021 | J3: ='Plan view'!E14 -> # of DCs and endpoints covered with deception
J4: =J8 -> 6 | K4: =K8 -> 0 | M4: =M8 -> 0 | N4: =N8 -> 0 | O4: =O8 -> 0 | P4: =P8 -> 0 | R4: =R8 -> 0 | S4: =S8 -> 2 | T4: =T8 -> 4 | U4: =U8 -> 6
J5: Target 31.12.21 | K5: Actuals 24.09.21 | M5: Actuals 17.09.21 | N5: Actuals 10.09.21 | O5: Actuals 03.09.21 | P5: Baseline 01.07.21 | R5: Plan 09/2021 | S5: Plan 10/2021 | T5: Plan 11/2021 | U5: Plan 12/2021 | W5: Comments
A6: .
J8: ='Plan view'!$H14 -> 6 | K8: 0 | M8: 0 | N8: 0 | O8: 0 | P8: ='Plan view'!$F14 -> 0 | R8: 0 | S8: 2 | T8: 4 | U8: 6

Sheet M283
H1: Focus Area | J1: Increase Detection | S1: All yellow marked columns to be filled out
A2: IT Security Initiative | J2: M283 | K2: #REF! | R2: Please fill in your monthly split of planned KPI target values (accumulated plan). Please leave a comment: In which CW will you report your first progress?
A3: =Overview!A3 -> Progress KPI Reporting 2021 | J3: ='Plan view'!E15 -> # of implemented cloud use cases
J4: =J8 -> 10 | K4: =K8 -> 1 | M4: =M8 -> 1 | N4: =N8 -> 1 | O4: =O8 -> 0 | P4: =P8 -> 0 | R4: =R8 -> 0 | S4: =S8 -> 2 | T4: =T8 -> 6 | U4: =U8 -> 10
J5: Target 31.12.21 | K5: Actuals 24.09.21 | M5: Actuals 17.09.21 | N5: Actuals 10.09.21 | O5: Actuals 03.09.21 | P5: Baseline 01.07.21 | R5: Plan 09/2021 | S5: Plan 10/2021 | T5: Plan 11/2021 | U5: Plan 12/2021 | W5: Comments
A6: .
J8: ='Plan view'!$H15 -> 10 | K8: 1 | M8: 1 | N8: 1 | O8: 0 | P8: ='Plan view'!$F15 -> 0 | R8: 0 | S8: 2 | T8: 6 | U8: 10

Sheet M284
H1: Focus Area | J1: Increase Detection | S1: All yellow marked columns to be filled out
A2: IT Security Initiative | J2: M284 | K2: #REF! | R2: Please fill in your monthly split of planned KPI target values (accumulated plan). Please leave a comment: In which CW will you report your first progress?
A3: =Overview!A3 -> Progress KPI Reporting 2021 | J3: ='Plan view'!E16 -> # of integrations or play books implemented
J4: =J8 -> 8 | K4: =K8 -> 4 | M4: =M8 -> 4 | N4: =N8 -> 4 | O4: =O8 -> 3 | P4: =P8 -> 0 | R4: =R8 -> 2 | S4: =S8 -> 4 | T4: =T8 -> 6 | U4: =U8 -> 8
J5: Target 31.12.21 | K5: Actuals 24.09.21 | M5: Actuals 17.09.21 | N5: Actuals 10.09.21 | O5: Actuals 03.09.21 | P5: Baseline 01.07.21 | R5: Plan 09/2021 | S5: Plan 10/2021 | T5: Plan 11/2021 | U5: Plan 12/2021 | W5: Comments
A6: .
J8: ='Plan view'!$H16 -> 8 | K8: 4 | M8: 4 | N8: 4 | O8: 3 | P8: ='Plan view'!$F16 -> 0 | R8: 2 | S8: 4 | T8: 6 | U8: 8

Sheet M285
H1: Focus Area | J1: Increase Detection | S1: All yellow marked columns to be filled out
A2: IT Security Initiative | J2: M285 | K2: #REF! | R2: Please fill in your monthly split of planned KPI target values (accumulated plan). Please leave a comment: In which CW will you report your first progress?
A3: =Overview!A3 -> Progress KPI Reporting 2021 | J3: ='Plan view'!E17 -> # of business critical applications moved to Enforce-Mode
J4: =J8 -> 30 | K4: =K8 -> 2 | M4: =M8 -> 2 | N4: =N8 -> 1 | O4: =O8 -> 0 | P4: =P8 -> 0 | R4: =R8 -> 8 | S4: =S8 -> 15 | T4: =T8 -> 25 | U4: =U8 -> 30
J5: Target 31.12.21 | K5: Actuals 24.09.21 | M5: Actuals 17.09.21 | N5: Actuals 10.09.21 | O5: Actuals 03.09.21 | P5: Baseline 01.07.21 | R5: Plan 09/2021 | S5: Plan 10/2021 | T5: Plan 11/2021 | U5: Plan 12/2021 | W5: Comments
A6: .
J8: ='Plan view'!$H17 -> 30 | K8: 2 | M8: 2 | N8: 1 | O8: 0 | P8: ='Plan view'!$F17 -> 0 | R8: 8 | S8: 15 | T8: 25 | U8: 30 | W8: First application moved to Enforce Mode in CW36
W9: First application moved to Enforce Mode in CW36
W10: First application moved to Enforce Mode in CW36
W11: First application moved to Enforce Mode in CW36
W12: First application moved to Enforce Mode in CW36
W13: First application moved to Enforce Mode in CW36
W14: First application moved to Enforce Mode in CW36
W15: First application moved to Enforce Mode in CW36
W16: First application moved to Enforce Mode in CW36
W17: First application moved to Enforce Mode in CW36
W18: First application moved to Enforce Mode in CW36
W19: First application moved to Enforce Mode in CW36

Sheet M286
H1: Focus Area | J1: Increase Detection | S1: All yellow marked columns to be filled out
A2: IT Security Initiative | J2: M286 | K2: #REF! | R2: Please fill in your monthly split of planned KPI target values (accumulated plan). Please leave a comment: In which CW will you report your first progress?
A3: =Overview!A3 -> Progress KPI Reporting 2021 | J3: ='Plan view'!E18 -> # of Reporting User Stories designed and User Stories implemented
J4: =J8 -> 12 | K4: =K8 -> 1 | M4: =M8 -> 1 | N4: =N8 -> 1 | O4: =O8 -> 0 | P4: =P8 -> 0 | R4: =R8 -> 4 | S4: =S8 -> 6 | T4: =T8 -> 8 | U4: =U8 -> 12
J5: Target 31.12.21 | K5: Actuals 24.09.21 | M5: Actuals 17.09.21 | N5: Actuals 10.09.21 | O5: Actuals 03.09.21 | P5: Baseline 01.07.21 | R5: Plan 09/2021 | S5: Plan 10/2021 | T5: Plan 11/2021 | U5: Plan 12/2021 | W5: Comments
A6: .
J8: ='Plan view'!$H18 -> 12 | K8: 1 | M8: 1 | N8: 1 | O8: 0 | P8: ='Plan view'!$F18 -> 0 | R8: 4 | S8: 6 | T8: 8 | U8: 12 | W8: As predicted more progress regarding the KPI's was archieved in CW37 with the User Story to Archer as a Sensor.
W9: As predicted more progress regarding the KPI's was archieved in CW37 with the User Story to Archer as a Sensor.
W10: As predicted more progress regarding the KPI's was archieved in CW37 with the User Story to Archer as a Sensor.
W11: As predicted more progress regarding the KPI's was archieved in CW37 with the User Story to Archer as a Sensor.
W12: As predicted more progress regarding the KPI's was archieved in CW37 with the User Story to Archer as a Sensor.
W13: As predicted more progress regarding the KPI's was archieved in CW37 with the User Story to Archer as a Sensor.
W14: As predicted more progress regarding the KPI's was archieved in CW37 with the User Story to Archer as a Sensor.
W15: As predicted more progress regarding the KPI's was archieved in CW37 with the User Story to Archer as a Sensor.
W16: As predicted more progress regarding the KPI's was archieved in CW37 with the User Story to Archer as a Sensor.
W17: As predicted more progress regarding the KPI's was archieved in CW37 with the User Story to Archer as a Sensor.
W18: As predicted more progress regarding the KPI's was archieved in CW37 with the User Story to Archer as a Sensor.
W19: As predicted more progress regarding the KPI's was archieved in CW37 with the User Story to Archer as a Sensor.

Sheet M287
H1: Focus Area | J1: Reduce Damage | S1: All yellow marked columns to be filled out
A2: IT Security Initiative | J2: M287 | K2: #REF! | R2: Please fill in your monthly split of planned KPI target values (accumulated plan). Please leave a comment: In which CW will you report your first progress?
A3: =Overview!A3 -> Progress KPI Reporting 2021 | J3: ='Plan view'!E19 -> # of OEs covered with Qualys agents on clients
J4: 20 | K4: =K88 -> 1 | M4: =M88 -> 1 | N4: =N88 -> 0 | O4: =O88 -> 0 | P4: =P88 -> 0 | R4: =R88 -> 6 | S4: =S88 -> 18 | T4: =T88 -> 42 | U4: =U88 -> 58
A5: Board Members | B5: H Ressort | C5: ITC Mapping | E5: Group Iso Function | F5: OEs ID | G5: CIM ID | H5: OE | J5: Target 31.12.21 | K5: Actuals 24.09.21 | M5: Actuals 17.09.21 | N5: Actuals 10.09.21 | O5: Actuals 03.09.21 | P5: Baseline 01.07.21 | R5: Plan 09/2021 | S5: Plan 10/2021 | T5: Plan 11/2021 | U5: Plan 12/2021 | W5: Comments
A6: .
A7: Bäte | B7: H1 CEO | C7: 1 | D7: Allianz SE, Allianz Europe | E7: Shared Services | F7: 1 | G7: AZSE | H7: Allianz SE | J7: 1 | K7: 0 | M7: 0 | N7: 0 | O7: 0 | P7: 0 | R7: 0 | S7: 0 | T7: 1 | U7: 1
C8: 2 | D8: TBD | E8: Asset & Overseas | F8: 2 | G8: AU | H8: Allianz Australia P&C | J8: 1 | K8: 0 | M8: 0 | N8: 0 | O8: 0 | P8: 0 | R8: 4 | S8: 12 | T8: 28 | U8: 39
A9: . | F9: ∑ | G9: ∑ | H9: 2 | J9: =SUM(J7:J8) -> 2 | K9: =SUM(K7:K8) -> 0 | M9: =SUM(M7:M8) -> 0 | N9: =SUM(N7:N8) -> 0 | O9: =SUM(O7:O8) -> 0 | P9: =SUM(P7:P8) -> 0 | R9: =SUM(R7:R8) -> 4 | S9: =SUM(S7:S8) -> 12 | T9: =SUM(T7:T8) -> 29 | U9: =SUM(U7:U8) -> 40
A10: .
A11: Thallinger | B11: H3 Investments Management | C11: 2 | D11: Allianz Investment | E11: Shared Services | F11: 3 | G11: ADEUS | H11: ADEUS Aktienregister-Service-GmbH | J11: 1 | K11: 0 | M11: 0 | N11: 0 | O11: 0 | P11: 0 | R11: 0 | S11: 1 | T11: 1 | U11: 1
E12: Europe 3 | F12: 4 | G12: AGL | H12: Allianz Global Life | J12: 1 | K12: 0 | M12: 0 | N12: 0 | O12: 0 | P12: 0 | R12: 0 | S12: 1 | T12: 1 | U12: 1
E13: Shared Services | F13: 5 | G13: AIM | H13: Allianz Investment Management (AIM) | J13: 1 | K13: 0 | M13: 0 | N13: 0 | O13: 0 | P13: 0 | R13: 0 | S13: 1 | T13: 1 | U13: 1
E14: Shared Services | F14: 6 | G14: ARE | H14: Allianz Real Estate (ARE) | J14: 0 | K14: 0 | M14: 0 | N14: 0 | O14: 0 | P14: 0 | R14: 0 | S14: 0 | T14: 0 | U14: 0
E15: TBD | F15: 7 | G15: AUL | H15: Allianz Australia Life | J15: 0 | K15: 0 | M15: 0 | N15: 0 | O15: 0 | P15: 0 | R15: 0 | S15: 0 | T15: 0 | U15: 0
E16: Shared Services | F16: 8 | G16: IDS | H16: Investment Data Services (IDS) | J16: 1 | K16: 0 | M16: 0 | N16: 0 | O16: 0 | P16: 0 | R16: 0 | S16: 1 | T16: 1 | U16: 1
A17: . | F17: ∑ | G17: ∑ | H17: 6 | J17: =SUM(J11:J16) -> 4 | K17: =SUM(K11:K16) -> 0 | M17: =SUM(M11:M16) -> 0 | N17: =SUM(N11:N16) -> 0 | O17: =SUM(O11:O16) -> 0 | P17: =SUM(P11:P16) -> 0 | R17: =SUM(R11:R16) -> 0 | S17: =SUM(S11:S16) -> 4 | T17: =SUM(T11:T16) -> 4 | U17: =SUM(U11:U16) -> 4
A18: .
A19: Mascher | B19: H4 Operations | C19: 3 | D19: Allianz Technology | E19: AZ Technology | F19: 9 | G19: AMOS | H19: Allianz Technology | J19: 0 | K19: 0 | M19: 0 | N19: 0 | O19: 0 | P19: 0 | R19: 0 | S19: 0 | T19: 0 | U19: 0
A20: . | F20: ∑ | G20: ∑ | H20: 1 | J20: =SUM(J19) -> 0 | K20: =SUM(K19) -> 0 | M20: =SUM(M19) -> 0 | N20: =SUM(N19) -> 0 | O20: =SUM(O19) -> 0 | P20: =SUM(P19) -> 0 | R20: =SUM(R19) -> 0 | S20: =SUM(S19) -> 0 | T20: =SUM(T19) -> 0 | U20: =SUM(U19) -> 0
A21: .
A22: Balbinot | B22: H5 Insurance Western & Southern Europe, AZAP | C22: 4 | D22: AZAP | E22: AZAP | F22: 10 | G22: CNPC | H22: Allianz China - P&C | J22: 1 | K22: 0 | M22: 0 | N22: 0 | O22: 0 | P22: 0 | R22: 0 | S22: 0 | T22: 0 | U22: 1
B23: H2 Finance, Controlling, Risk | E23: AZAP | F23: 11 | G23: CNH | H23: Allianz China - Holding | J23: 1 | K23: 0 | M23: 0 | N23: 0 | O23: 0 | P23: 0 | R23: 0 | S23: 0 | T23: 0 | U23: 1
B24: H2 Finance, Controlling, Risk | E24: AZAP | F24: 12 | G24: ID | H24: Allianz Indonesia | J24: 0 | K24: 0 | M24: 0 | N24: 0 | O24: 0 | P24: 0 | R24: 0 | S24: 0 | T24: 0 | U24: 0
B25: H2 Finance, Controlling, Risk | E25: AZAP | F25: 13 | G25: LAPC | H25: Allianz Laos | J25: 0 | K25: 0 | M25: 0 | N25: 0 | O25: 0 | P25: 0 | R25: 0 | S25: 0 | T25: 0 | U25: 0
B26: H2 Finance, Controlling, Risk | E26: AZAP | F26: 14 | G26: MY | H26: Allianz Malaysia | J26: 0 | K26: 0 | M26: 0 | N26: 0 | O26: 0 | P26: 0 | R26: 0 | S26: 0 | T26: 0 | U26: 0
B27: H2 Finance, Controlling, Risk | E27: AZAP | F27: 15 | G27: PH | H27: Allianz Philippine - L&H | J27: 1 | K27: 0 | M27: 0 | N27: 0 | O27: 0 | P27: 0 | R27: 0 | S27: 0 | T27: 1 | U27: 1
B28: H2 Finance, Controlling, Risk | E28: AZAP | F28: 16 | G28: LK | H28: Allianz Sri Lanka | J28: 0 | K28: 0 | M28: 0 | N28: 0 | O28: 0 | P28: 0 | R28: 0 | S28: 0 | T28: 0 | U28: 0
B29: H2 Finance, Controlling, Risk | E29: AZAP | F29: 17 | G29: AS | H29: Allianz Singapore | J29: 1 | K29: 0 | M29: 0 | N29: 0 | O29: 0 | P29: 0 | R29: 1 | S29: 1 | T29: 1 | U29: 1
B30: H2 Finance, Controlling, Risk | E30: AZAP | F30: 18 | G30: TWL | H30: Allianz Taiwan - Life | J30: 1 | K30: 0 | M30: 0 | N30: 0 | O30: 0 | P30: 0 | R30: 0 | S30: 0 | T30: 0 | U30: 1
B31: H2 Finance, Controlling, Risk | E31: AZAP | F31: 19 | G31: TH | H31: Allianz Thailand | J31: 1 | K31: 0 | M31: 0 | N31: 0 | O31: 0 | P31: 0 | R31: 0 | S31: 0 | T31: 0 | U31: 1
B32: H2 Finance, Controlling, Risk | E32: AZAP | F32: 20 | G32: FIN | H32: FinOS - Holding | J32: 0 | K32: 0 | M32: 0 | N32: 0 | O32: 0 | P32: 0 | R32: 0 | S32: 0 | T32: 0 | U32: 0
B33: H2 Finance, Controlling, Risk | F33: ∑ | G33: ∑ | H33: 11 | J33: =SUM(J22:J32) -> 6 | K33: =SUM(K22:K32) -> 0 | M33: =SUM(M22:M32) -> 0 | N33: =SUM(N22:N32) -> 0 | O33: =SUM(O22:O32) -> 0 | P33: =SUM(P22:P32) -> 0 | R33: =SUM(R22:R32) -> 1 | S33: =SUM(S22:S32) -> 1 | T33: =SUM(T22:T32) -> 2 | U33: =SUM(U22:U32) -> 6
B34: H2 Finance, Controlling, Risk | C34: 5 | D34: Allianz Benelux | E34: Europe 2 | F34: 21 | G34: BLX | H34: Allianz Benelux | J34: 0 | K34: 0 | M34: 0 | N34: 0 | O34: 0 | P34: 0 | R34: 0 | S34: 0 | T34: 0 | U34: 0
B35: H2 Finance, Controlling, Risk | C35: 6 | D35: Allianz France | E35: Europe 2 | F35: 22 | G35: FR | H35: Allianz France | J35: 0 | K35: 0 | M35: 0 | N35: 0 | O35: 0 | P35: 0 | R35: 0 | S35: 0 | T35: 0 | U35: 0
B36: H2 Finance, Controlling, Risk | C36: 7 | D36: Allianz Greece | E36: Europe 3 | F36: 23 | G36: GR | H36: Allianz Greece | J36: 0 | K36: 0 | M36: 0 | N36: 0 | O36: 0 | P36: 0 | R36: 0 | S36: 0 | T36: 0 | U36: 0
B37: H2 Finance, Controlling, Risk | C37: 8 | D37: Allianz Italy | E37: Europe 3 | F37: 24 | G37: IT | H37: Allianz Italy | J37: 0 | K37: 0 | M37: 0 | N37: 0 | O37: 0 | P37: 0 | R37: 0 | S37: 0 | T37: 0 | U37: 0
B38: H2 Finance, Controlling, Risk | C38: 9 | D38: Allianz Turkey | E38: Europe 3 | F38: 25 | G38: TR | H38: Allianz Turkey | J38: 0 | K38: 0 | M38: 0 | N38: 0 | O38: 0 | P38: 0 | R38: 0 | S38: 0 | T38: 0 | U38: 0
A39: . | F39: ∑ | G39: ∑ | H39: 16 | J39: =SUM(J33:J38) -> 6 | K39: =SUM(K33:K38) -> 0 | M39: =SUM(M33:M38) -> 0 | N39: =SUM(N33:N38) -> 0 | O39: =SUM(O33:O38) -> 0 | P39: =SUM(P33:P38) -> 0 | R39: =SUM(R33:R38) -> 1 | S39: =SUM(S33:S38) -> 1 | T39: =SUM(T33:T38) -> 2 | U39: =SUM(U33:U38) -> 6
A40: .
...

Sheet M288
H1: Focus Area | J1: Reduce Damage | S1: All yellow marked columns to be filled out
A2: IT Security Initiative | J2: M288 | K2: #REF! | R2: Please fill in your monthly split of planned KPI target values (accumulated plan). Please leave a comment: In which CW will you report your first progress?
A3: =Overview!A3 -> Progress KPI Reporting 2021 | J3: ='Plan view'!E20 -> # of reached milestones
J4: =J8 -> 4 | K4: =K8 -> 1 | M4: =M8 -> 1 | N4: =N8 -> 1 | O4: =O8 -> 0 | P4: =P8 -> 0 | R4: =R8 -> 1 | S4: =S8 -> 1 | T4: =T8 -> 2 | U4: =U8 -> 4
J5: Target 31.12.21 | K5: Actuals 24.09.21 | M5: Actuals 17.09.21 | N5: Actuals 10.09.21 | O5: Actuals 03.09.21 | P5: Baseline 01.07.21 | R5: Plan 09/2021 | S5: Plan 10/2021 | T5: Plan 11/2021 | U5: Plan 12/2021 | W5: Comments
A6: .
J8: ='Plan view'!$H20 -> 4 | K8: 1 | M8: 1 | N8: 1 | O8: 0 | P8: ='Plan view'!$F20 -> 0 | R8: 1 | S8: 1 | T8: 2 | U8: 4 | W8: - Preparation of the pilot in Unterföhring including AMC, printer (start onbording workshops for each end point class) - prepare the discussion with Ireland in parallel. Which device classes are in use and how are they integrated into NAC - Setting up a Sup-PKI for NAC only
W9: - Preparation of the pilot in Unterföhring including AMC, printer (start onbording workshops for each end point class) - prepare the discussion with Ireland in parallel. Which device classes are in use and how are they integrated into NAC - Setting up a Sup-PKI for NAC only
W10: - Preparation of the pilot in Unterföhring including AMC, printer (start onbording workshops for each end point class) - prepare the discussion with Ireland in parallel. Which device classes are in use and how are they integrated into NAC - Setting up a Sup-PKI for NAC only
W11: - Preparation of the pilot in Unterföhring including AMC, printer (start onbording workshops for each end point class) - prepare the discussion with Ireland in parallel. Which device classes are in use and how are they integrated into NAC - Setting up a Sup-PKI for NAC only
W12: - Preparation of the pilot in Unterföhring including AMC, printer (start onbording workshops for each end point class) - prepare the discussion with Ireland in parallel. Which device classes are in use and how are they integrated into NAC - Setting up a Sup-PKI for NAC only
W13: - Preparation of the pilot in Unterföhring including AMC, printer (start onbording workshops for each end point class) - prepare the discussion with Ireland in parallel. Which device classes are in use and how are they integrated into NAC - Setting up a Sup-PKI for NAC only
W14: - Preparation of the pilot in Unterföhring including AMC, printer (start onbording workshops for each end point class) - prepare the discussion with Ireland in parallel. Which device classes are in use and how are they integrated into NAC - Setting up a Sup-PKI for NAC only
W15: - Preparation of the pilot in Unterföhring including AMC, printer (start onbording workshops for each end point class) - prepare the discussion with Ireland in parallel. Which device classes are in use and how are they integrated into NAC - Setting up a Sup-PKI for NAC only
W16: - Preparation of the pilot in Unterföhring including AMC, printer (start onbording workshops for each end point class) - prepare the discussion with Ireland in parallel. Which device classes are in use and how are they integrated into NAC - Setting up a Sup-PKI for NAC only
W17: - Preparation of the pilot in Unterföhring including AMC, printer (start onbording workshops for each end point class) - prepare the discussion with Ireland in parallel. Which device classes are in use and how are they integrated into NAC - Setting up a Sup-PKI for NAC only
W18: - Preparation of the pilot in Unterföhring including AMC, printer (start onbording workshops for each end point class) - prepare the discussion with Ireland in parallel. Which device classes are in use and how are they integrated into NAC - Setting up a Sup-PKI for NAC only
W19: - Preparation of the pilot in Unterföhring including AMC, printer (start onbording workshops for each end point class) - prepare the discussion with Ireland in parallel. Which device classes are in use and how are they integrated into NAC - Setting up a Sup-PKI for NAC only

Sheet M289
H1: Focus Area | J1: Reduce Damage | S1: All yellow marked columns to be filled out
A2: IT Security Initiative | J2: M289 | K2: #REF! | R2: Please fill in your monthly split of planned KPI target values (accumulated plan). Please leave a comment: In which CW will you report your first progress?
A3: =Overview!A3 -> Progress KPI Reporting 2021 | J3: ='Plan view'!E21 -> # of users rolled-out to password manager service
J4: =J8 -> 1000 | K4: =K8 -> 0 | M4: =M8 -> 0 | N4: =N8 -> 0 | O4: =O8 -> 0 | P4: =P8 -> 0 | R4: =R8 -> 0 | S4: =S8 -> 0 | T4: =T8 -> 0 | U4: =U8 -> 1000
J5: Target 31.12.21 | K5: Actuals 24.09.21 | M5: Actuals 17.09.21 | N5: Actuals 10.09.21 | O5: Actuals 03.09.21 | P5: Baseline 01.07.21 | R5: Plan 09/2021 | S5: Plan 10/2021 | T5: Plan 11/2021 | U5: Plan 12/2021 | W5: Comments
A6: .
J8: ='Plan view'!$H21 -> 1000 | K8: 0 | M8: 0 | N8: 0 | O8: 0 | P8: ='Plan view'!$F21 -> 0 | R8: 0 | S8: 0 | T8: 0 | U8: 1000 | W8: We plan to rollout the password manager service to 1k users after our running PoC, the vendor decision, the contracting and the service creation. First rollout is planned for CW48.
W9: We plan to rollout the password manager service to 1k users after our running PoC, the vendor decision, the contracting and the service creation. First rollout is planned for CW48.
W10: We plan to rollout the password manager service to 1k users after our running PoC, the vendor decision, the contracting and the service creation. First rollout is planned for CW48.
W11: We plan to rollout the password manager service to 1k users after our running PoC, the vendor decision, the contracting and the service creation. First rollout is planned for CW48.
W12: We plan to rollout the password manager service to 1k users after our running PoC, the vendor decision, the contracting and the service creation. First rollout is planned for CW48.
W13: We plan to rollout the password manager service to 1k users after our running PoC, the vendor decision, the contracting and the service creation. First rollout is planned for CW48.
W14: We plan to rollout the password manager service to 1k users after our running PoC, the vendor decision, the contracting and the service creation. First rollout is planned for CW48.
W15: We plan to rollout the password manager service to 1k users after our running PoC, the vendor decision, the contracting and the service creation. First rollout is planned for CW48.
W16: We plan to rollout the password manager service to 1k users after our running PoC, the vendor decision, the contracting and the service creation. First rollout is planned for CW48.
W17: We plan to rollout the password manager service to 1k users after our running PoC, the vendor decision, the contracting and the service creation. First rollout is planned for CW48.
W18: We plan to rollout the password manager service to 1k users after our running PoC, the vendor decision, the contracting and the service creation. First rollout is planned for CW48.
W19: We plan to rollout the password manager service to 1k users after our running PoC, the vendor decision, the contracting and the service creation. First rollout is planned for CW48.

Sheet M290
